Workbook

Sheet Geral
A1: Nome do Exercício | B1: Link
A2: Supino com barra | B2: https://musclewiki.com/pt-br/barbell/male/chest/barbell-bench-press
A3: Mergulho na caixa | B3: https://musclewiki.com/pt-br/bodyweight/male/triceps/box-dips
A4: Crucifixo Inclinado com Halteres | B4: https://musclewiki.com/pt-br/dumbbells/male/anterior-deltoid/dumbbell-incline-chest-flys
A5: Supino Inclinado com Barra | B5: https://musclewiki.com/pt-br/barbell/male/anterior-deltoid/barbell-incline-bench-press
A6: Supino com Kettlebell (Unilateral) | B6: https://musclewiki.com/pt-br/kettlebells/male/triceps/kettlebell-chest-press-single
A7: Crucifixo unilateral com kettlebell | B7: https://musclewiki.com/pt-br/kettlebells/male/chest/kettlebell-single-arm-chest-fly
A8: Desenvolvimento Unilateral com Kettlebell | B8: https://musclewiki.com/pt-br/kettlebells/male/triceps/kettlebell-single-arm-press
A9: Flexão com passagem por cima do kettlebell | B9: https://musclewiki.com/pt-br/kettlebells/male/triceps/kettlebell-walkover-pushup
A10: Alongamento do Peitoral — Variação Quatro | B10: https://musclewiki.com/pt-br/stretches/male/chest/chest-stretch-variation-four
A11: Alongamento do Peito — Variação Três | B11: https://musclewiki.com/pt-br/stretches/male/chest/chest-stretch-variation-three
A12: Alongamento do Peitoral — Variação Dois | B12: https://musclewiki.com/pt-br/stretches/male/chest/chest-stretch-variation-two
... A234: Dumbbell Single Arm Incline Chest Press | B234: https://musclewiki.com/pt-br/dumbbells/male/chest/dumbbell-single-arm-incline-chest-press
B235: Link
A236: Puxada na máquina | B236: https://musclewiki.com/pt-br/machine/male/lats/machine-pulldown
A237: Remada Sentada na Máquina | B237: https://musclewiki.com/pt-br/machine/male/biceps/machine-seated-cable-row
A238: Barra Fixa | B238: https://musclewiki.com/pt-br/bodyweight/male/traps-middle/pull-ups
A239: Remada Bilateral com Halteres | B239: https://musclewiki.com/pt-br/dumbbells/male/traps-middle/dumbbell-row-bilateral
A240: Remada Curvada com Barra | B240: https://musclewiki.com/pt-br/barbell/male/biceps/barbell-bent-over-row
A241: Remada com kettlebell (unilateral) | B241: https://musclewiki.com/pt-br/kettlebells/male/biceps/kettlebell-row-single
A242: Extensão de Ombro com Kettlebell | B242: https://musclewiki.com/pt-br/kettlebells/male/lats/kettlebell-shoulder-extension
A243: Remada Unilateral com Kettlebell | B243: https://musclewiki.com/pt-br/kettlebells/male/biceps/kettlebell-single-arm-row
A244: Pulôver com kettlebell | B244: https://musclewiki.com/pt-br/kettlebells/male/lats/kettlebell-pullover
A245: Alongamento de Dorsais — Variação Três | B245: https://musclewiki.com/pt-br/stretches/male/lats/lats-stretch-variation-three
A246: Alongamento dos Dorsais — Variação Dois | B246: https://musclewiki.com/pt-br/stretches/male/lats/lats-stretch-variation-two
A247: Alongamento de Dorsais — Variação Um | B247: https://musclewiki.com/pt-br/stretches/male/lats/lats-stretch-variation-one
... A271: Ponte de Glúteos com Anilha para Pullover | B271: https://musclewiki.com/pt-br/plate/male/glutes/plate-glute-bridge-to-pullover
A272: Remada unilateral (Lawnmower)
A273: Remada cortador de grama com haltere (joelho apoiado) | B273: https://musclewiki.com/pt-br/dumbbells/male/biceps/dumbbell-knee-lawnmower-row
A274: Remada Supinada com Halteres | B274: https://musclewiki.com/pt-br/dumbbells/male/biceps/dumbbell-supinated-row
A275: Remada TRX com rotação | B275: https://musclewiki.com/pt-br/trx/male/biceps/trx-rotating-row
A276: Remada unilateral no TRX | B276: https://musclewiki.com/pt-br/trx/male/biceps/trx-single-arm-row
A277: Barra Fixa (pegada supinada) | B277: https://musclewiki.com/pt-br/bodyweight/male/biceps/chin-ups
A278: Remada com Barra na Landmine | B278: https://musclewiki.com/pt-br/barbell/male/biceps/barbell-landmine-row
A279: Remada com pegada de pinça na anilha | B279: https://musclewiki.com/pt-br/plate/male/biceps/plate-pinch-grip-row
A280: Levantamento Terra com Pegada em Pinça no Disco | B280: https://musclewiki.com/pt-br/plate/male/lowerback/plate-pinch-grip-deadlift
A281: Flexão para Remada Renegade | B281: https://musclewiki.com/pt-br/dumbbells/male/abdominals/pushup-to-renegade-row
A282: TRX Rollout Abdominal | B282: https://musclewiki.com/pt-br/trx/male/lowerback/trx-ab-rollout
A283: TRX Rollout Abdominal Ajoelhado | B283: https://musclewiki.com/pt-br/trx/male/abdominals/trx-kneeling-ab-rollout
A284: Postura da Criança — Braços Estendidos | B284: https://musclewiki.com/pt-br/yoga/male/lats/child-pose-arms-extended
...

Sheet Randomizador
A1: Inferiores | D1: Superiores | G1: Geral | J1: Peito + triceps + ombro | M1: Costas + biceps + core | P1: Circuito
A3: Mobilidade | B3: =IFERROR(__xludf.DUMMYFUNCTION("INDEX( FILTER( Geral!A2:A3114, ISNUMBER(SEARCH(""alongamento"", Geral!A2:A3114)) + ISNUMBER(SEARCH(""mobilidade"", Geral!A2:A3114)) ), RANDBETWEEN( 1, COUNTA( FILTER( Geral!A2:A3114, ISNUMBER(SEARCH(""alonga"&"mento"", Geral!A2:A3114)) + ISNUMBER(SEARCH(""mobilidade"", Geral!A2:A3114)) ) ) ) )"),"Alongamento de Ombros — Variação 2") -> Alongamento de Ombros — Variação 2 | D3: Mobilidade | E3: =IFERROR(__xludf.DUMMYFUNCTION("INDEX( FILTER( Geral!A2:A3114, ISNUMBER(SEARCH(""alongamento"", Geral!A2:A3114)) + ISNUMBER(SEARCH(""mobilidade"", Geral!A2:A3114)) ), RANDBETWEEN( 1, COUNTA( FILTER( Geral!A2:A3114, ISNUMBER(SEARCH(""alonga"&"mento"", Geral!A2:A3114)) + ISNUMBER(SEARCH(""mobilidade"", Geral!A2:A3114)) ) ) ) )"),"Alongamento de Bíceps Variação Um") -> Alongamento de Bíceps Variação Um | G3: Mobilidade | H3: =IFERROR(__xludf.DUMMYFUNCTION("INDEX( FILTER( Geral!A2:A3114, ISNUMBER(SEARCH(""alongamento"", Geral!A2:A3114)) + ISNUMBER(SEARCH(""mobilidade"", Geral!A2:A3114)) ), RANDBETWEEN( 1, COUNTA( FILTER( Geral!A2:A3114, ISNUMBER(SEARCH(""alonga"&"mento"", Geral!A2:A3114)) + ISNUMBER(SEARCH(""mobilidade"", Geral!A2:A3114)) ) ) ) )"),"Alongamento de Ombros — Variação Quatro") -> Alongamento de Ombros — Variação Quatro | J3: Mobilidade | K3: =IFERROR(__xludf.DUMMYFUNCTION("INDEX( FILTER( Geral!A2:A3114, ISNUMBER(SEARCH(""alongamento"", Geral!A2:A3114)) + ISNUMBER(SEARCH(""mobilidade"", Geral!A2:A3114)) ), RANDBETWEEN( 1, COUNTA( FILTER( Geral!A2:A3114, ISNUMBER(SEARCH(""alonga"&"mento"", Geral!A2:A3114)) + ISNUMBER(SEARCH(""mobilidade"", Geral!A2:A3114)) ) ) ) )"),"Alongamento Lateral Sentado") -> Alongamento Lateral Sentado | M3: Mobilidade | N3: =IFERROR(__xludf.DUMMYFUNCTION("INDEX( FILTER( Geral!A2:A3114, ISNUMBER(SEARCH(""alongamento"", Geral!A2:A3114)) + ISNUMBER(SEARCH(""mobilidade"", Geral!A2:A3114)) ), RANDBETWEEN( 1, COUNTA( FILTER( Geral!A2:A3114, ISNUMBER(SEARCH(""alonga"&"mento"", Geral!A2:A3114)) + ISNUMBER(SEARCH(""mobilidade"", Geral!A2:A3114)) ) ) ) )"),"Alongamento de Quadril Noventa Noventa com Peso Corporal") -> Alongamento de Quadril Noventa Noventa com Peso Corporal | P3: Quadríceps | Q3: =IFERROR(__xludf.DUMMYFUNCTION("INDEX( FILTER('Quadríceps'!A2:A398, ISNUMBER(SEARCH(""Peso corporal"", 'Quadríceps'!A2:A398))), RANDBETWEEN( 1, COUNTA(FILTER('Quadríceps'!A2:A398, ISNUMBER(SEARCH(""Peso corporal"", 'Quadríceps'!A2:A398)))) ) )"),"Afundo Alternado Com Peso Corporal") -> Afundo Alternado Com Peso Corporal
A4: Quadríceps | B4: {=INDEX('Quadríceps'!A2:A398, RANDBETWEEN(1, COUNTA('Quadríceps'!A2:A398)))} -> Afundo Curtsy Com Haltere Em Taça | D4: Peitoral | E4: {=INDEX(Peitoral!A2:A234, RANDBETWEEN(1, COUNTA(Peitoral!A2:A234)))} -> Flexão para Remada Renegade | G4: Peitoral | H4: =IFERROR(__xludf.DUMMYFUNCTION("INDEX( FILTER(Peitoral!A2:A234, ISNUMBER(SEARCH(""Peso corporal"", Peitoral!A2:A234))), RANDBETWEEN( 1, COUNTA(FILTER(Peitoral!A2:A234, ISNUMBER(SEARCH(""Peso corporal"", Peitoral!A2:A234)))) ) )"),"Flexão Explosiva (Peso Corporal)") -> Flexão Explosiva (Peso Corporal) | J4: Peitoral | K4: {=INDEX(Peitoral!A2:A234, RANDBETWEEN(1, COUNTA(Peitoral!A2:A234)))} -> Puxada de Joelho e Rotação Lombar | M4: Costas | N4: {=INDEX(Costas!A2:A147, RANDBETWEEN(1, COUNTA(Costas!A2:A147)))} -> Remada unilateral (Lawnmower) | P4: Peitoral | Q4: {=INDEX(Peitoral!A2:A234, RANDBETWEEN(1, COUNTA(Peitoral!A2:A234)))} -> Flexões com as Mãos Levantadas (Peso corporal)
A5: Quadríceps | B5: {=INDEX('Quadríceps'!A2:A399, RANDBETWEEN(1, COUNTA('Quadríceps'!A2:A399)))} -> Afundo Reverso com Halteres | D5: Costas | E5: {=INDEX(Costas!A2:A147, RANDBETWEEN(1, COUNTA(Costas!A2:A147)))} -> Máquina de Remada T com Carga de Placas | G5: Quadríceps | H5: =IFERROR(__xludf.DUMMYFUNCTION("INDEX( FILTER('Quadríceps'!A2:A398, ISNUMBER(SEARCH(""Peso corporal"", 'Quadríceps'!A2:A398))), RANDBETWEEN( 1, COUNTA(FILTER('Quadríceps'!A2:A398, ISNUMBER(SEARCH(""Peso corporal"", 'Quadríceps'!A2:A398)))) ) )"),"Step-up reverso (Peso corporal)") -> Step-up reverso (Peso corporal) | J5: Peitoral | K5: {=INDEX(Peitoral!A2:A234, RANDBETWEEN(1, COUNTA(Peitoral!A2:A234)))} -> Supino Vitruvian | M5: Costas | N5: {=INDEX(Costas!A2:A147, RANDBETWEEN(1, COUNTA(Costas!A2:A147)))} -> Remadas T-Bar na Landmine | P5: Costas | Q5: =IFERROR(__xludf.DUMMYFUNCTION("INDEX( FILTER(Costas!A2:A147, ISNUMBER(SEARCH(""Peso corporal"", Costas!A2:A147))), RANDBETWEEN( 1, COUNTA(FILTER(Costas!A2:A147, ISNUMBER(SEARCH(""Peso corporal"", Costas!A2:A147)))) ) )"),"Giro com Barra Fixa (peso corporal)") -> Giro com Barra Fixa (peso corporal)
A6: Glúteo | B6: {=INDEX('Glúteo'!A2:A632, RANDBETWEEN(1, COUNTA('Glúteo'!A2:A632)))} -> Kettlebell Squat Clean And Jerk | D6: Bíceps | E6: {=INDEX('Bíceps'!A2:A201, RANDBETWEEN(1, COUNTA('Bíceps'!A2:A201)))} -> Remada Pendlay com pegada supinada | G6: Costas | H6: =IFERROR(__xludf.DUMMYFUNCTION("INDEX( FILTER(Costas!A2:A147, ISNUMBER(SEARCH(""Peso corporal"", Costas!A2:A147))), RANDBETWEEN( 1, COUNTA(FILTER(Costas!A2:A147, ISNUMBER(SEARCH(""Peso corporal"", Costas!A2:A147)))) ) )"),"Barra Fixa (pegada supinada) (peso corporal)") -> Barra Fixa (pegada supinada) (peso corporal) | J6: Peitoral | K6: {=INDEX(Peitoral!A2:A234, RANDBETWEEN(1, COUNTA(Peitoral!A2:A234)))} -> Voador Peitoral com Rotação Interna com Elástico | M6: Costas | N6: {=INDEX(Costas!A2:A147, RANDBETWEEN(1, COUNTA(Costas!A2:A147)))} -> Remada Unilateral com Halter | P6: Cardio | Q6: =IFERROR(__xludf.DUMMYFUNCTION("INDEX( FILTER(Geral!A2:A3114, ISNUMBER(SEARCH(""cardio"", Geral!A2:A3114))), RANDBETWEEN( 1, COUNTA(FILTER(Geral!A2:A3114, ISNUMBER(SEARCH(""cardio"", Geral!A2:A3114)))) ) )"),"Cardio — Polichinelos Seal") -> Cardio — Polichinelos Seal
A7: Posterior | B7: {=INDEX(Posterior!A2:A185, RANDBETWEEN(1, COUNTA(Posterior!A2:A185)))} -> Curl de Posterior de Coxa com Sliders | D7: Tríceps | E7: {=INDEX('Tríceps'!A2:A259, RANDBETWEEN(1, COUNTA('Tríceps'!A2:A259)))} -> Extensão de Tríceps Acima da Cabeça com Faixa | G7: Glúteo | H7: =IFERROR(__xludf.DUMMYFUNCTION("INDEX( FILTER('Glúteo'!A2:A634, ISNUMBER(SEARCH(""Peso corporal"", 'Glúteo'!A2:A634))), RANDBETWEEN( 1, COUNTA(FILTER('Glúteo'!A2:A634, ISNUMBER(SEARCH(""Peso corporal"", 'Glúteo'!A2:A634)))) ) )"),"Afundos Laterais (peso corporal)") -> Afundos Laterais (peso corporal) | J7: Tríceps | K7: {=INDEX('Tríceps'!A2:A259, RANDBETWEEN(1, COUNTA('Tríceps'!A2:A259)))} -> Flexões Diamante com Peso | M7: Bíceps | N7: {=INDEX('Bíceps'!A2:A201, RANDBETWEEN(1, COUNTA('Bíceps'!A2:A201)))} -> Remada Unilateral no Cabo com Pegada Neutra | P7: Quadríceps | Q7: =IFERROR(__xludf.DUMMYFUNCTION("INDEX( FILTER('Quadríceps'!A2:A402, ISNUMBER(SEARCH(""Peso corporal"", 'Quadríceps'!A2:A402))), RANDBETWEEN( 1, COUNTA(FILTER('Quadríceps'!A2:A402, ISNUMBER(SEARCH(""Peso corporal"", 'Quadríceps'!A2:A402)))) ) )"),"Afundo Reverso (Peso corporal)") -> Afundo Reverso (Peso corporal)
A8: Panturrilha | B8: {=INDEX(Panturrilha!A2:A89, RANDBETWEEN(1, COUNTA(Posterior!A2:A89)))} -> Máquina de Elevação de Panturrilha com Carga de Placas | D8: Ombro | E8: {=INDEX(Ombro!A2:A377, RANDBETWEEN(1, COUNTA(Ombro!A2:A377)))} -> Alongamento de Ombros — Variação 1 | G8: Cardio | H8: =IFERROR(__xludf.DUMMYFUNCTION("INDEX( FILTER(Geral!A2:A3114, ISNUMBER(SEARCH(""cardio"", Geral!A2:A3114))), RANDBETWEEN( 1, COUNTA(FILTER(Geral!A2:A3114, ISNUMBER(SEARCH(""cardio"", Geral!A2:A3114)))) ) )"),"Remada Cardio (Ergômetro) — Só Braços") -> Remada Cardio (Ergômetro) — Só Braços | J8: Tríceps | K8: {=INDEX('Tríceps'!A2:A259, RANDBETWEEN(1, COUNTA('Tríceps'!A2:A259)))} -> Tríceps Testa (Landmine) | M8: Bíceps | N8: {=INDEX('Bíceps'!A2:A201, RANDBETWEEN(1, COUNTA('Bíceps'!A2:A201)))} -> Cable Pull Around | P8: Cardio | Q8: =IFERROR(__xludf.DUMMYFUNCTION("INDEX( FILTER(Geral!A2:A3114, ISNUMBER(SEARCH(""cardio"", Geral!A2:A3114))), RANDBETWEEN( 1, COUNTA(FILTER(Geral!A2:A3114, ISNUMBER(SEARCH(""cardio"", Geral!A2:A3114)))) ) )"),"Cardio — In and Outs") -> Cardio — In and Outs
A9: Linha posterior | B9: {=INDEX('Linha posterior'!A2:A185, RANDBETWEEN(1, COUNTA('Linha posterior'!A2:A185)))} -> Rotação Lombar 5 | D9: Abdominais | E9: {=INDEX(Abdominais!A2:A259, RANDBETWEEN(1, COUNTA(Abdominais!A2:A259)))} -> Band Low To High Pallof Press Wood Chopper | G9: Abdominais | H9: {=INDEX(Abdominais!A2:A259, RANDBETWEEN(1, COUNTA(Abdominais!A2:A259)))} -> Woodchopper com haltere (meio ajoelhado) | J9: Ombro | K9: {=INDEX(Ombro!A2:A377, RANDBETWEEN(1, COUNTA(Ombro!A2:A377)))} -> Clean and Press com Kettlebell | M9: Abdominais | N9: {=INDEX(Abdominais!A2:A259, RANDBETWEEN(1, COUNTA(Abdominais!A2:A259)))} -> Abdominal Na Polia Em Pé | P9: Abdominais | Q9: =IFERROR(__xludf.DUMMYFUNCTION("INDEX( FILTER(Abdominais!A2:A259, ISNUMBER(SEARCH(""Peso corporal"", Abdominais!A2:A259))), RANDBETWEEN( 1, COUNTA(FILTER(Abdominais!A2:A259, ISNUMBER(SEARCH(""Peso corporal"", Abdominais!A2:A259)))) ) )"),"Rotação da Coluna Torácica com Peso Corporal") -> Rotação da Coluna Torácica com Peso Corporal
A10: Adutor | B10: =IFERROR(__xludf.DUMMYFUNCTION("INDEX( FILTER(Geral!A2:A3114, ISNUMBER(SEARCH(""adução"", Geral!A2:A3114))), RANDBETWEEN( 1, COUNTA(FILTER(Geral!A2:A3114, ISNUMBER(SEARCH(""adução"", Geral!A2:A3114)))) ) )"),"Adução de Quadril com Elástico") -> Adução de Quadril com Elástico | D10: Trapézio | E10: {=INDEX('Trapézio'!A3:A147, RANDBETWEEN(1, COUNTA('Trapézio'!A3:A147)))} -> Caminhada Com Disco Sobre a Cabeça | J10: Ombro | K10: {=INDEX(Ombro!A2:A377, RANDBETWEEN(1, COUNTA(Ombro!A2:A377)))} -> Remada para Deltoide Posterior com Pesa Russa | M10: Abdominais | N10: {=INDEX(Abdominais!A2:A259, RANDBETWEEN(1, COUNTA(Abdominais!A2:A259)))} -> Woodchopper com haltere | P10: Abdominais | Q10: =IFERROR(__xludf.DUMMYFUNCTION("INDEX( FILTER(Abdominais!A3:A260, ISNUMBER(SEARCH(""Peso corporal"", Abdominais!A3:A260))), RANDBETWEEN( 1, COUNTA(FILTER(Abdominais!A3:A260, ISNUMBER(SEARCH(""Peso corporal"", Abdominais!A3:A260)))) ) )"),"Russian Twist (peso corporal)") -> Russian Twist (peso corporal)
A13: Fichas:
A15: Geral: | B15: Geral
A16: A/B: | B16: Inferiores/superiores
A17: A/B/G: | B17: Inferiores/superiores/Geral
A18: A/B/C: | B18: Peito + triceps + ombro / Costas + biceps + core / Inferiores
A19: Circuito: | B19: Circuito

Sheet Peitoral
A1: Nome do Exercício | B1: Link
A2: Supino com barra | B2: https://musclewiki.com/pt-br/barbell/male/chest/barbell-bench-press
A3: Mergulho na caixa (Peso corporal) | B3: https://musclewiki.com/pt-br/bodyweight/male/triceps/box-dips
A4: Crucifixo Inclinado com Halteres | B4: https://musclewiki.com/pt-br/dumbbells/male/anterior-deltoid/dumbbell-incline-chest-flys
A5: Supino Inclinado com Barra | B5: https://musclewiki.com/pt-br/barbell/male/anterior-deltoid/barbell-incline-bench-press
A6: Supino com Kettlebell (Unilateral) | B6: https://musclewiki.com/pt-br/kettlebells/male/triceps/kettlebell-chest-press-single
A7: Crucifixo unilateral com kettlebell | B7: https://musclewiki.com/pt-br/kettlebells/male/chest/kettlebell-single-arm-chest-fly
A8: Desenvolvimento Unilateral com Kettlebell | B8: https://musclewiki.com/pt-br/kettlebells/male/triceps/kettlebell-single-arm-press
A9: Flexão com passagem por cima do kettlebell | B9: https://musclewiki.com/pt-br/kettlebells/male/triceps/kettlebell-walkover-pushup
A10: Alongamento do Peitoral — Variação Quatro | B10: https://musclewiki.com/pt-br/stretches/male/chest/chest-stretch-variation-four
A11: Alongamento do Peito — Variação Três | B11: https://musclewiki.com/pt-br/stretches/male/chest/chest-stretch-variation-three
A12: Alongamento do Peitoral — Variação Dois | B12: https://musclewiki.com/pt-br/stretches/male/chest/chest-stretch-variation-two
... A234: Dumbbell Single Arm Incline Chest Press | B234: https://musclewiki.com/pt-br/dumbbells/male/chest/dumbbell-single-arm-incline-chest-press

Sheet Costas
B1: Link
A2: Puxada na máquina | B2: https://musclewiki.com/pt-br/machine/male/lats/machine-pulldown
A3: Remada Sentada na Máquina | B3: https://musclewiki.com/pt-br/machine/male/biceps/machine-seated-cable-row
A4: Barra Fixa (peso corporal) | B4: https://musclewiki.com/pt-br/bodyweight/male/traps-middle/pull-ups
A5: Remada Bilateral com Halteres | B5: https://musclewiki.com/pt-br/dumbbells/male/traps-middle/dumbbell-row-bilateral
A6: Remada Curvada com Barra | B6: https://musclewiki.com/pt-br/barbell/male/biceps/barbell-bent-over-row
A7: Remada com kettlebell (unilateral) | B7: https://musclewiki.com/pt-br/kettlebells/male/biceps/kettlebell-row-single
A8: Extensão de Ombro com Kettlebell | B8: https://musclewiki.com/pt-br/kettlebells/male/lats/kettlebell-shoulder-extension
A9: Remada Unilateral com Kettlebell | B9: https://musclewiki.com/pt-br/kettlebells/male/biceps/kettlebell-single-arm-row
A10: Pulôver com kettlebell | B10: https://musclewiki.com/pt-br/kettlebells/male/lats/kettlebell-pullover
A11: Alongamento de Dorsais — Variação Três | B11: https://musclewiki.com/pt-br/stretches/male/lats/lats-stretch-variation-three
A12: Alongamento dos Dorsais — Variação Dois | B12: https://musclewiki.com/pt-br/stretches/male/lats/lats-stretch-variation-two
A13: Alongamento de Dorsais — Variação Um | B13: https://musclewiki.com/pt-br/stretches/male/lats/lats-stretch-variation-one
... A37: Ponte de Glúteos com Anilha para Pullover | B37: https://musclewiki.com/pt-br/plate/male/glutes/plate-glute-bridge-to-pullover
A38: Remada unilateral (Lawnmower)
A39: Remada cortador de grama com haltere (joelho apoiado) | B39: https://musclewiki.com/pt-br/dumbbells/male/biceps/dumbbell-knee-lawnmower-row
A40: Remada Supinada com Halteres | B40: https://musclewiki.com/pt-br/dumbbells/male/biceps/dumbbell-supinated-row
A41: Remada TRX com rotação | B41: https://musclewiki.com/pt-br/trx/male/biceps/trx-rotating-row
A42: Remada unilateral no TRX | B42: https://musclewiki.com/pt-br/trx/male/biceps/trx-single-arm-row
A43: Barra Fixa (pegada supinada) (peso corporal) | B43: https://musclewiki.com/pt-br/bodyweight/male/biceps/chin-ups
A44: Remada com Barra na Landmine | B44: https://musclewiki.com/pt-br/barbell/male/biceps/barbell-landmine-row
A45: Remada com pegada de pinça na anilha | B45: https://musclewiki.com/pt-br/plate/male/biceps/plate-pinch-grip-row
A46: Levantamento Terra com Pegada em Pinça no Disco | B46: https://musclewiki.com/pt-br/plate/male/lowerback/plate-pinch-grip-deadlift
A47: Flexão para Remada Renegade | B47: https://musclewiki.com/pt-br/dumbbells/male/abdominals/pushup-to-renegade-row
A48: TRX Rollout Abdominal | B48: https://musclewiki.com/pt-br/trx/male/lowerback/trx-ab-rollout
A49: TRX Rollout Abdominal Ajoelhado | B49: https://musclewiki.com/pt-br/trx/male/abdominals/trx-kneeling-ab-rollout
A50: Postura da Criança — Braços Estendidos | B50: https://musclewiki.com/pt-br/yoga/male/lats/child-pose-arms-extended
... A147: Dumbbell Single Arm Rear Delt Row | B147: https://musclewiki.com/pt-br/dumbbells/male/biceps/dumbbell-single-arm-rear-delt-row

Sheet Bíceps
A1: Nome do Exercício | B1: Link
A2: Rosca Direta | B2: https://musclewiki.com/pt-br/barbell/male/biceps/barbell-curl
A3: Rosca direta com halteres | B3: https://musclewiki.com/pt-br/dumbbells/male/biceps/dumbbell-curl
A4: Rosca martelo com halteres | B4: https://musclewiki.com/pt-br/dumbbells/male/biceps/dumbbell-hammer-curl
A5: Rosca Goblet com Kettlebell | B5: https://musclewiki.com/pt-br/kettlebells/male/biceps/kettlebell-goblet-curl
A6: Rosca Concentrada com Kettlebell | B6: https://musclewiki.com/pt-br/kettlebells/male/biceps/kettlebell-concentration-curl
A7: Rosca Scott com kettlebell | B7: https://musclewiki.com/pt-br/kettlebells/male/biceps/kettlebell-preacher-curl
A8: Rosca Unilateral com Kettlebell | B8: https://musclewiki.com/pt-br/kettlebells/male/biceps/kettlebell-single-arm-curl
A9: Alongamento de Bíceps Variação Cinco | B9: https://musclewiki.com/pt-br/stretches/male/biceps/biceps-stretch-variation-five
A10: Variação Quatro do Alongamento de Bíceps | B10: https://musclewiki.com/pt-br/stretches/male/biceps/biceps-stretch-variation-four
A11: Alongamento de Bíceps — Variação Três | B11: https://musclewiki.com/pt-br/stretches/male/biceps/biceps-stretch-variation-three
A12: Alongamento de bíceps — Variação Dois | B12: https://musclewiki.com/pt-br/stretches/male/biceps/biceps-stretch-variation-two
... A201: Dumbbell Single Arm Seated Hammer Curl | B201: https://musclewiki.com/pt-br/dumbbells/male/biceps/dumbbell-single-arm-seated-hammer-curl

Sheet Trapézio
A1: Nome do Exercício | B1: Link
A2: Encolhimento de Ombros com Kettlebell Silverback (Unilateral) | B2: https://musclewiki.com/pt-br/kettlebells/male/traps-middle/kettlebell-silverback-shrug-single
A3: Encolhimento de Ombros Inclinado com Kettlebell | B3: https://musclewiki.com/pt-br/kettlebells/male/traps-middle/kettlebell-incline-shrug
A4: Flexão Pike Elevada | B4: https://musclewiki.com/pt-br/bodyweight/male/traps-middle/elevated-pike-press
A5: Encolhimento de Ombros no Cabo Silverback | B5: https://musclewiki.com/pt-br/cables/male/traps-middle/cable-silverback-shrug
A6: Encolhimento Horizontal de Ombros com Elástico | B6: https://musclewiki.com/pt-br/band/male/traps-middle/band-horizontal-shrug
A7: Encolhimento de ombros deitado com halteres Silverback | B7: https://musclewiki.com/pt-br/dumbbells/male/traps-middle/dumbbell-laying-silverback-shrug
A8: Encolhimento com Halteres Silverback | B8: https://musclewiki.com/pt-br/dumbbells/male/traps-middle/dumbbell-silverback-shrug
A9: Flexão Pike com Peso Corporal | B9: https://musclewiki.com/pt-br/bodyweight/male/traps-middle/bodyweight-pike-press
A10: Levantamento Alto com Barra | B10: https://musclewiki.com/pt-br/barbell/male/traps-middle/barbell-high-pull
A11: Levantamento Alto com Pegada Larga de Barra | B11: https://musclewiki.com/pt-br/barbell/male/traps-middle/barbell-snatch-grip-high-pull
A12: Alongamento do Trapézio e da Parte Média das Costas — Variação Dois | B12: https://musclewiki.com/pt-br/stretches/male/traps-middle/traps-mid-back-stretch-variation-two
... A148: Band Seated Single Arm Pulldown | B148: https://musclewiki.com/pt-br/band/male/lats/band-seated-single-arm-pulldown

Sheet Tríceps
A1: Nome do Exercício | B1: Link
A2: Extensão de Tríceps Sentado com Halter Acima da Cabeça | B2: https://musclewiki.com/pt-br/dumbbells/male/triceps/dumbbell-seated-overhead-tricep-extension
A3: Tríceps na Polia com Barra em V | B3: https://musclewiki.com/pt-br/machine/male/triceps/machine-cable-v-bar-push-downs
A4: Mergulho no banco | B4: https://musclewiki.com/pt-br/bodyweight/male/triceps/bench-dips
A5: Tríceps Testa com Barra | B5: https://musclewiki.com/pt-br/barbell/male/triceps/barbell-laying-triceps-extensions
A6: Tríceps testa com kettlebell | B6: https://musclewiki.com/pt-br/kettlebells/male/triceps/kettlebell-skull-crusher
A7: Extensão de tríceps em pé com kettlebell | B7: https://musclewiki.com/pt-br/kettlebells/male/triceps/kettlebell-standing-tricep-extension
A8: Tríceps Testa Declinada com Kettlebell | B8: https://musclewiki.com/pt-br/kettlebells/male/triceps/kettlebell-decline-skull-crusher
A9: Tate Press com Kettlebell | B9: https://musclewiki.com/pt-br/kettlebells/male/triceps/kettlebell-tate-press
A10: Alongamento de Tríceps — Variação Três | B10: https://musclewiki.com/pt-br/stretches/male/triceps/triceps-stretch-variation-three
A11: Alongamento de Tríceps — Variação 2 | B11: https://musclewiki.com/pt-br/stretches/male/triceps/triceps-stretch-variation-two
A12: Alongamento de Tríceps Variação Um | B12: https://musclewiki.com/pt-br/stretches/male/triceps/triceps-stretch-variation-one
... A259: Cable Single Arm Pushdown | B259: https://musclewiki.com/pt-br/cables/male/triceps/cable-single-arm-pushdown

Sheet Ombro
A1: Nome do Exercício | B1: Link
A2: Elevação Lateral com Halteres | B2: https://musclewiki.com/pt-br/dumbbells/male/shoulders/dumbbell-lateral-raise
A3: Crucifixo inverso com halteres | B3: https://musclewiki.com/pt-br/dumbbells/male/shoulders/dumbbell-rear-delt-fly
A4: Face Pulls na Polia com Corda | B4: https://musclewiki.com/pt-br/cables/male/shoulders/machine-face-pulls
A5: Desenvolvimento com Halteres Sentado | B5: https://musclewiki.com/pt-br/dumbbells/male/shoulders/dumbbell-seated-overhead-press
A6: Elevação Frontal com Halteres | B6: https://musclewiki.com/pt-br/dumbbells/male/shoulders/dumbbell-front-raise
A7: Crucifixo Inverso Sentado com Halteres | B7: https://musclewiki.com/pt-br/dumbbells/male/shoulders/dumbbell-seated-rear-delt-fly
A8: Remada para Deltoide Posterior com Pesa Russa | B8: https://musclewiki.com/pt-br/kettlebells/male/biceps/kettlebell-rear-delt-row
A9: Elevação frontal com kettlebell | B9: https://musclewiki.com/pt-br/kettlebells/male/shoulders/kettlebell-front-raise
A10: Voador Inverso Unilateral com Kettlebell | B10: https://musclewiki.com/pt-br/kettlebells/male/shoulders/kettlebell-single-arm-rear-delt-fly
A11: Elevação Lateral com Kettlebell (Alavanca Longa) | B11: https://musclewiki.com/pt-br/kettlebells/male/shoulders/kettlebell-long-lever-lateral-raise
A12: Elevação Lateral Unilateral com Kettlebell | B12: https://musclewiki.com/pt-br/kettlebells/male/shoulders/kettlebell-single-arm-lateral-raise
... A377: Máquina de Voo Reverso | B377: https://musclewiki.com/pt-br/machine/male/posterior-deltoid/machine-reverse-fly

Sheet Quadríceps
A1: corr | B1: Link
A2: Agachamento com barra | B2: https://musclewiki.com/pt-br/barbell/male/glutes/barbell-squat
A3: Leg press na máquina | B3: https://musclewiki.com/pt-br/machine/male/glutes/machine-leg-press
A4: Extensão de Pernas na Máquina | B4: https://musclewiki.com/pt-br/machine/male/quads/machine-leg-extension
A5: Agachamento Goblet com Haltere | B5: https://musclewiki.com/pt-br/dumbbells/male/glutes/dumbbell-goblet-squat
A6: Afundo Búlgaro (Peso corporal) | B6: https://musclewiki.com/pt-br/bodyweight/male/glutes/bulgarian-split-squat
A7: Step-up com pesa russa | B7: https://musclewiki.com/pt-br/kettlebells/male/glutes/kettlebell-step-up
A8: Agachamento Goblet com Kettlebell | B8: https://musclewiki.com/pt-br/kettlebells/male/glutes/kettlebell-goblet-squat
A9: Agachamento Goblet com Kettlebell — calcanhares elevados | B9: https://musclewiki.com/pt-br/kettlebells/male/glutes/kettlebell-heels-up-goblet-squat
A10: Avanço Reverso com Kettlebell (Braço Único) | B10: https://musclewiki.com/pt-br/kettlebells/male/glutes/kettlebell-single-arm-reverse-lunge
A11: Passada Frontal Unilateral com Kettlebell | B11: https://musclewiki.com/pt-br/kettlebells/male/glutes/kettlebell-single-arm-forward-lunge
A12: Afundo Lateral com Kettlebell (Unilateral) | B12: https://musclewiki.com/pt-br/kettlebells/male/glutes/kettlebell-lateral-lunge-single
... A398: Elevação de Pernas em Inclinação no Chão | B398: https://musclewiki.com/pt-br/recovery/male/rectus-femoris/leg-raise-straight-incline-seated

Sheet Glúteo
A1: Nome do Exercício | B1: Link
A2: Ponte de Glúteos (peso corporal) | B2: https://musclewiki.com/pt-br/bodyweight/male/glutes/glute-bridge
A3: Elevação de Quadril com Barra | B3: https://musclewiki.com/pt-br/barbell/male/glutes/barbell-hip-thrust
A4: Ponte de Glúteos Unilateral (peso corporal) | B4: https://musclewiki.com/pt-br/bodyweight/male/glutes/single-leg-glute-bridge
A5: Elevação de Quadril com Kettlebell | B5: https://musclewiki.com/pt-br/kettlebells/male/glutes/kettlebell-glute-bridge
A6: Ponte de Glúteos Unilateral com Kettlebell | B6: https://musclewiki.com/pt-br/kettlebells/male/glutes/kettlebell-single-leg-glute-bridge
A7: Elevação de quadril com kettlebell | B7: https://musclewiki.com/pt-br/kettlebells/male/glutes/kettlebell-hip-thrust
A8: Elevação de Quadril Unilateral com Kettlebell | B8: https://musclewiki.com/pt-br/kettlebells/male/glutes/kettlebell-single-leg-hip-thrust
A9: Alongamento de Glúteos — Variação Três | B9: https://musclewiki.com/pt-br/stretches/male/glutes/glutes-stretch-variation-three
A10: Alongamento de Glúteos — Variação Dois | B10: https://musclewiki.com/pt-br/stretches/male/glutes/glutes-stretch-variation-two
A11: Alongamento de Glúteos — Variação Um | B11: https://musclewiki.com/pt-br/stretches/male/glutes/glutes-stretch-variation-one
A12: Abdução de Quadril em Pé na Polia | B12: https://musclewiki.com/pt-br/cables/male/glutes/cable-standing-hip-abduction
... A632: Agachamento no Smith | B632: https://musclewiki.com/pt-br/smith-machine/male/gluteus-maximus/smith-machine-squat

Sheet Posterior
A1: Nome do Exercício | B1: Link
A2: Stiff com barra | B2: https://musclewiki.com/pt-br/barbell/male/glutes/barbell-stiff-leg-deadlifts
A3: Flexora para posteriores da coxa na máquina | B3: https://musclewiki.com/pt-br/machine/male/hamstrings/machine-hamstring-curl
A4: Levantamento Terra com Kettlebell (Unilateral) | B4: https://musclewiki.com/pt-br/kettlebells/male/traps-middle/kettlebell-deadlift-single
A5: Swing com kettlebell | B5: https://musclewiki.com/pt-br/kettlebells/male/lowerback/kettlebell-swing
A6: Levantamento Terra Unilateral Com Kettlebell | B6: https://musclewiki.com/pt-br/kettlebells/male/lowerback/kettlebell-single-leg-deadlift
A7: Levantamento Terra com Kettlebell em Base Escalonada (Unilateral) | B7: https://musclewiki.com/pt-br/kettlebells/male/lowerback/kettlebell-staggered-deadlift-single
A8: Alongamento do Posterior de Coxa — Variação Quatro | B8: https://musclewiki.com/pt-br/stretches/male/hamstrings/hamstrings-stretch-variation-four
A9: Alongamento Dos Posteriores De Coxa Variação Três | B9: https://musclewiki.com/pt-br/stretches/male/hamstrings/hamstrings-stretch-variation-three
A10: Alongamento dos Isquiotibiais — Variação Dois | B10: https://musclewiki.com/pt-br/stretches/male/hamstrings/hamstrings-stretch-variation-two
A11: Alongamento dos Isquiotibiais Variação Um | B11: https://musclewiki.com/pt-br/stretches/male/hamstrings/hamstrings-stretch-variation-one
A12: Good Mornings | B12: https://musclewiki.com/pt-br/bodyweight/male/lowerback/good-mornings
... A185: Band Standing Good Morning | B185: https://musclewiki.com/pt-br/band/male/lowerback/band-standing-good-morning

Sheet Panturrilha
A1: Nome do Exercício | B1: Link
A2: Elevação de Panturrilha em Pé na Máquina | B2: https://musclewiki.com/pt-br/machine/male/calves/machine-standing-calf-raises
A3: Elevação de Panturrilhas Sentado na Máquina | B3: https://musclewiki.com/pt-br/machine/male/calves/machine-seated-calf-raises
A4: Elevação de Panturrilha Unilateral com Kettlebell | B4: https://musclewiki.com/pt-br/kettlebells/male/calves/kettlebell-single-leg-calf-raise
A5: Elevação de Panturrilha com Kettlebell | B5: https://musclewiki.com/pt-br/kettlebells/male/calves/kettlebell-calf-raise
A6: Elevação Sentada de Panturrilha com Pesa Russa | B6: https://musclewiki.com/pt-br/kettlebells/male/calves/kettlebell-seated-calf-raise
A7: Alongamento De Panturrilhas Variação Três | B7: https://musclewiki.com/pt-br/stretches/male/calves/calves-stretch-variation-three
A8: Alongamento de panturrilhas — Variação Dois | B8: https://musclewiki.com/pt-br/stretches/male/calves/calves-stretch-variation-two
A9: Alongamento de Panturrilhas Variação Um | B9: https://musclewiki.com/pt-br/stretches/male/calves/calves-stretch-variation-one
A10: Andar na ponta dos pés | B10: https://musclewiki.com/pt-br/bodyweight/male/calves/tip-toe-walking
A11: Elevação de panturrilha | B11: https://musclewiki.com/pt-br/bodyweight/male/calves/calf-raises
A12: Elevação de Panturrilha em Caminhada | B12: https://musclewiki.com/pt-br/bodyweight/male/calves/walking-calf-raises
... A89: Elevação de Panturrilha com uma Perna com Peso Corporal | B89: https://musclewiki.com/pt-br/bodyweight/male/calves/bodyweight-single-leg-calf-raise

Sheet Abdominais
A1: Nome do Exercício | B1: Link
A2: Abdominais | B2: https://musclewiki.com/pt-br/bodyweight/male/abdominals/crunches
A3: Elevação de pernas deitado | B3: https://musclewiki.com/pt-br/bodyweight/male/abdominals/laying-leg-raises
A4: Rollouts na Máquina | B4: https://musclewiki.com/pt-br/machine/male/abdominals/machine-roll-outs
A5: Abdominal com Pesa Russa | B5: https://musclewiki.com/pt-br/kettlebells/male/abdominals/kettlebell-situp
A6: Alongamento Abdominal Variação Quatro | B6: https://musclewiki.com/pt-br/stretches/male/abdominals/abdominals-stretch-variation-four
A7: Alongamento de Abdominais Variação Três | B7: https://musclewiki.com/pt-br/stretches/male/abdominals/abdominals-stretch-variation-three
A8: Alongamento Abdominal Variação Dois | B8: https://musclewiki.com/pt-br/stretches/male/abdominals/abdominals-stretch-variation-two
A9: Alongamento dos Abdominais — Variação Um | B9: https://musclewiki.com/pt-br/stretches/male/abdominals/abdominals-stretch-variation-one
A10: Prancha nos antebraços | B10: https://musclewiki.com/pt-br/bodyweight/male/abdominals/forearm-plank
A11: Elevação de Joelhos na Barra Fixa | B11: https://musclewiki.com/pt-br/bodyweight/male/abdominals/hanging-knee-raises
A12: Rollouts com barra | B12: https://musclewiki.com/pt-br/barbell/male/abdominals/barbell-roll-outs
... A259: Dumbbell Feet Down Russian Twist | B259: https://musclewiki.com/pt-br/dumbbells/male/obliques/dumbbell-feet-down-russian-twist

Sheet Linha posterior
A1: Nome do Exercício | B1: Link
A2: Extensão lombar 45° na máquina | B2: https://musclewiki.com/pt-br/machine/male/lowerback/machine-45-degree-back-extension
A3: Alongamento Lombar Variação Quatro | B3: https://musclewiki.com/pt-br/stretches/male/lowerback/lower-back-stretch-variation-four
A4: Alongamento Lombar — Variação Três | B4: https://musclewiki.com/pt-br/stretches/male/lowerback/lower-back-stretch-variation-three
A5: Alongamento lombar Variação Dois | B5: https://musclewiki.com/pt-br/stretches/male/lowerback/lower-back-stretch-variation-two
A6: Alongamento Lombar Variação Um | B6: https://musclewiki.com/pt-br/stretches/male/lowerback/lower-back-stretch-variation-one
A7: Supermans | B7: https://musclewiki.com/pt-br/bodyweight/male/lowerback/supermans
A8: Levantamento Terra com Anilha | B8: https://musclewiki.com/pt-br/plate/male/lowerback/plate-deadlift
A9: Superman com halteres | B9: https://musclewiki.com/pt-br/dumbbells/male/lowerback/dumbbell-superman
A10: Levantamento Terra com Barra | B10: https://musclewiki.com/pt-br/barbell/male/traps-middle/barbell-deadlift
A11: Remada Bilateral com Halteres | B11: https://musclewiki.com/pt-br/dumbbells/male/traps-middle/dumbbell-row-bilateral
A12: Levantamento Terra com Kettlebell (Unilateral) | B12: https://musclewiki.com/pt-br/kettlebells/male/traps-middle/kettlebell-deadlift-single
... A185: Band Standing Good Morning | B185: https://musclewiki.com/pt-br/band/male/lowerback/band-standing-good-morning

Sheet Antebraço
A1: Nome do Exercício | B1: Link
A2: Rosca De Punho Com Barra Atrás Das Costas | B2: https://musclewiki.com/pt-br/barbell/male/forearms/barbell-behind-the-back-wrist-curl
A3: Rosca de punho com halteres | B3: https://musclewiki.com/pt-br/dumbbells/male/forearms/dumbbell-wrist-curl
A4: Rosca de punho com barra | B4: https://musclewiki.com/pt-br/barbell/male/forearms/barbell-wrist-curl
A5: Caminhada do Fazendeiro com kettlebell | B5: https://musclewiki.com/pt-br/kettlebells/male/forearms/kettlebell-farmers-carry
A6: Extensão de Punho com Kettlebell | B6: https://musclewiki.com/pt-br/kettlebells/male/forearms/kettlebell-wrist-extension
A7: Rosca de punho com kettlebell | B7: https://musclewiki.com/pt-br/kettlebells/male/forearms/kettlebell-wrist-curl
A8: Alongamento de Antebraços Variação Quatro | B8: https://musclewiki.com/pt-br/stretches/male/forearms/forearms-stretch-variation-four
A9: Alongamento de Antebraços Variação Três | B9: https://musclewiki.com/pt-br/stretches/male/forearms/forearms-stretch-variation-three
A10: Alongamento dos Antebraços — Variação Dois | B10: https://musclewiki.com/pt-br/stretches/male/forearms/forearms-stretch-variation-two
A11: Alongamento dos Antebraços — Variação Um | B11: https://musclewiki.com/pt-br/stretches/male/forearms/forearms-stretch-variation-one
A12: Rosca de Punho no Cabo | B12: https://musclewiki.com/pt-br/cables/male/forearms/cable-wrist-curl
... A107: Dumbbell Single Arm Bench Wrist Extension | B107: https://musclewiki.com/pt-br/dumbbells/male/wrist-extensors/dumbbell-single-arm-bench-wrist-extension
